2021-12-02 14:33:01,314 - INFO - bot started!
2021-12-02 14:33:01,315 - INFO - Scheduler started
2021-12-02 14:33:05,808 - ERROR - Error while getting Updates: Conflict: terminated by other getUpdates request; make sure that only one bot instance is running
2021-12-02 14:33:05,808 - ERROR - No error handlers are registered, logging exception.
Traceback (most recent call last):
  File "C:\Python310\lib\site-packages\telegram\ext\updater.py", line 646, in _network_loop_retry
    if not action_cb():
  File "C:\Python310\lib\site-packages\telegram\ext\updater.py", line 597, in polling_action_cb
    updates = self.bot.get_updates(
  File "C:\Python310\lib\site-packages\telegram\ext\extbot.py", line 222, in get_updates
    updates = super().get_updates(
  File "C:\Python310\lib\site-packages\telegram\bot.py", line 130, in decorator
    result = func(*args, **kwargs)
  File "C:\Python310\lib\site-packages\telegram\bot.py", line 2861, in get_updates
    self._post(
  File "C:\Python310\lib\site-packages\telegram\bot.py", line 295, in _post
    return self.request.post(
  File "C:\Python310\lib\site-packages\telegram\utils\request.py", line 361, in post
    result = self._request_wrapper(
  File "C:\Python310\lib\site-packages\telegram\utils\request.py", line 283, in _request_wrapper
    raise Conflict(message)
telegram.error.Conflict: Conflict: terminated by other getUpdates request; make sure that only one bot instance is running
2021-12-02 14:33:08,402 - INFO - User None press /start
2021-12-02 14:33:12,499 - ERROR - Error while getting Updates: Conflict: terminated by other getUpdates request; make sure that only one bot instance is running
2021-12-02 14:33:12,500 - ERROR - No error handlers are registered, logging exception.
Traceback (most recent call last):
  File "C:\Python310\lib\site-packages\telegram\ext\updater.py", line 646, in _network_loop_retry
    if not action_cb():
  File "C:\Python310\lib\site-packages\telegram\ext\updater.py", line 597, in polling_action_cb
    updates = self.bot.get_updates(
  File "C:\Python310\lib\site-packages\telegram\ext\extbot.py", line 222, in get_updates
    updates = super().get_updates(
  File "C:\Python310\lib\site-packages\telegram\bot.py", line 130, in decorator
    result = func(*args, **kwargs)
  File "C:\Python310\lib\site-packages\telegram\bot.py", line 2861, in get_updates
    self._post(
  File "C:\Python310\lib\site-packages\telegram\bot.py", line 295, in _post
    return self.request.post(
  File "C:\Python310\lib\site-packages\telegram\utils\request.py", line 361, in post
    result = self._request_wrapper(
  File "C:\Python310\lib\site-packages\telegram\utils\request.py", line 283, in _request_wrapper
    raise Conflict(message)
telegram.error.Conflict: Conflict: terminated by other getUpdates request; make sure that only one bot instance is running
2021-12-02 14:33:18,100 - ERROR - Error while getting Updates: Conflict: terminated by other getUpdates request; make sure that only one bot instance is running
2021-12-02 14:33:18,100 - ERROR - No error handlers are registered, logging exception.
Traceback (most recent call last):
  File "C:\Python310\lib\site-packages\telegram\ext\updater.py", line 646, in _network_loop_retry
    if not action_cb():
  File "C:\Python310\lib\site-packages\telegram\ext\updater.py", line 597, in polling_action_cb
    updates = self.bot.get_updates(
  File "C:\Python310\lib\site-packages\telegram\ext\extbot.py", line 222, in get_updates
    updates = super().get_updates(
  File "C:\Python310\lib\site-packages\telegram\bot.py", line 130, in decorator
    result = func(*args, **kwargs)
  File "C:\Python310\lib\site-packages\telegram\bot.py", line 2861, in get_updates
    self._post(
  File "C:\Python310\lib\site-packages\telegram\bot.py", line 295, in _post
    return self.request.post(
  File "C:\Python310\lib\site-packages\telegram\utils\request.py", line 361, in post
    result = self._request_wrapper(
  File "C:\Python310\lib\site-packages\telegram\utils\request.py", line 283, in _request_wrapper
    raise Conflict(message)
telegram.error.Conflict: Conflict: terminated by other getUpdates request; make sure that only one bot instance is running
2021-12-02 14:33:24,968 - ERROR - Error while getting Updates: Conflict: terminated by other getUpdates request; make sure that only one bot instance is running
2021-12-02 14:33:24,968 - ERROR - No error handlers are registered, logging exception.
Traceback (most recent call last):
  File "C:\Python310\lib\site-packages\telegram\ext\updater.py", line 646, in _network_loop_retry
    if not action_cb():
  File "C:\Python310\lib\site-packages\telegram\ext\updater.py", line 597, in polling_action_cb
    updates = self.bot.get_updates(
  File "C:\Python310\lib\site-packages\telegram\ext\extbot.py", line 222, in get_updates
    updates = super().get_updates(
  File "C:\Python310\lib\site-packages\telegram\bot.py", line 130, in decorator
    result = func(*args, **kwargs)
  File "C:\Python310\lib\site-packages\telegram\bot.py", line 2861, in get_updates
    self._post(
  File "C:\Python310\lib\site-packages\telegram\bot.py", line 295, in _post
    return self.request.post(
  File "C:\Python310\lib\site-packages\telegram\utils\request.py", line 361, in post
    result = self._request_wrapper(
  File "C:\Python310\lib\site-packages\telegram\utils\request.py", line 283, in _request_wrapper
    raise Conflict(message)
telegram.error.Conflict: Conflict: terminated by other getUpdates request; make sure that only one bot instance is running
2021-12-02 14:33:33,698 - ERROR - Error while getting Updates: Conflict: terminated by other getUpdates request; make sure that only one bot instance is running
2021-12-02 14:33:33,699 - ERROR - No error handlers are registered, logging exception.
Traceback (most recent call last):
  File "C:\Python310\lib\site-packages\telegram\ext\updater.py", line 646, in _network_loop_retry
    if not action_cb():
  File "C:\Python310\lib\site-packages\telegram\ext\updater.py", line 597, in polling_action_cb
    updates = self.bot.get_updates(
  File "C:\Python310\lib\site-packages\telegram\ext\extbot.py", line 222, in get_updates
    updates = super().get_updates(
  File "C:\Python310\lib\site-packages\telegram\bot.py", line 130, in decorator
    result = func(*args, **kwargs)
  File "C:\Python310\lib\site-packages\telegram\bot.py", line 2861, in get_updates
    self._post(
  File "C:\Python310\lib\site-packages\telegram\bot.py", line 295, in _post
    return self.request.post(
  File "C:\Python310\lib\site-packages\telegram\utils\request.py", line 361, in post
    result = self._request_wrapper(
  File "C:\Python310\lib\site-packages\telegram\utils\request.py", line 283, in _request_wrapper
    raise Conflict(message)
telegram.error.Conflict: Conflict: terminated by other getUpdates request; make sure that only one bot instance is running
2021-12-02 14:33:42,246 - ERROR - Error while getting Updates: Conflict: terminated by other getUpdates request; make sure that only one bot instance is running
2021-12-02 14:33:42,246 - ERROR - No error handlers are registered, logging exception.
Traceback (most recent call last):
  File "C:\Python310\lib\site-packages\telegram\ext\updater.py", line 646, in _network_loop_retry
    if not action_cb():
  File "C:\Python310\lib\site-packages\telegram\ext\updater.py", line 597, in polling_action_cb
    updates = self.bot.get_updates(
  File "C:\Python310\lib\site-packages\telegram\ext\extbot.py", line 222, in get_updates
    updates = super().get_updates(
  File "C:\Python310\lib\site-packages\telegram\bot.py", line 130, in decorator
    result = func(*args, **kwargs)
  File "C:\Python310\lib\site-packages\telegram\bot.py", line 2861, in get_updates
    self._post(
  File "C:\Python310\lib\site-packages\telegram\bot.py", line 295, in _post
    return self.request.post(
  File "C:\Python310\lib\site-packages\telegram\utils\request.py", line 361, in post
    result = self._request_wrapper(
  File "C:\Python310\lib\site-packages\telegram\utils\request.py", line 283, in _request_wrapper
    raise Conflict(message)
telegram.error.Conflict: Conflict: terminated by other getUpdates request; make sure that only one bot instance is running
2021-12-02 14:33:55,020 - ERROR - Error while getting Updates: Conflict: terminated by other getUpdates request; make sure that only one bot instance is running
2021-12-02 14:33:55,020 - ERROR - No error handlers are registered, logging exception.
Traceback (most recent call last):
  File "C:\Python310\lib\site-packages\telegram\ext\updater.py", line 646, in _network_loop_retry
    if not action_cb():
  File "C:\Python310\lib\site-packages\telegram\ext\updater.py", line 597, in polling_action_cb
    updates = self.bot.get_updates(
  File "C:\Python310\lib\site-packages\telegram\ext\extbot.py", line 222, in get_updates
    updates = super().get_updates(
  File "C:\Python310\lib\site-packages\telegram\bot.py", line 130, in decorator
    result = func(*args, **kwargs)
  File "C:\Python310\lib\site-packages\telegram\bot.py", line 2861, in get_updates
    self._post(
  File "C:\Python310\lib\site-packages\telegram\bot.py", line 295, in _post
    return self.request.post(
  File "C:\Python310\lib\site-packages\telegram\utils\request.py", line 361, in post
    result = self._request_wrapper(
  File "C:\Python310\lib\site-packages\telegram\utils\request.py", line 283, in _request_wrapper
    raise Conflict(message)
telegram.error.Conflict: Conflict: terminated by other getUpdates request; make sure that only one bot instance is running
2021-12-02 14:34:14,106 - ERROR - Error while getting Updates: Conflict: terminated by other getUpdates request; make sure that only one bot instance is running
2021-12-02 14:34:14,106 - ERROR - No error handlers are registered, logging exception.
Traceback (most recent call last):
  File "C:\Python310\lib\site-packages\telegram\ext\updater.py", line 646, in _network_loop_retry
    if not action_cb():
  File "C:\Python310\lib\site-packages\telegram\ext\updater.py", line 597, in polling_action_cb
    updates = self.bot.get_updates(
  File "C:\Python310\lib\site-packages\telegram\ext\extbot.py", line 222, in get_updates
    updates = super().get_updates(
  File "C:\Python310\lib\site-packages\telegram\bot.py", line 130, in decorator
    result = func(*args, **kwargs)
  File "C:\Python310\lib\site-packages\telegram\bot.py", line 2861, in get_updates
    self._post(
  File "C:\Python310\lib\site-packages\telegram\bot.py", line 295, in _post
    return self.request.post(
  File "C:\Python310\lib\site-packages\telegram\utils\request.py", line 361, in post
    result = self._request_wrapper(
  File "C:\Python310\lib\site-packages\telegram\utils\request.py", line 283, in _request_wrapper
    raise Conflict(message)
telegram.error.Conflict: Conflict: terminated by other getUpdates request; make sure that only one bot instance is running
2021-12-02 14:34:36,172 - INFO - Received signal 2 (SIGINT), stopping...
2021-12-02 14:34:36,172 - INFO - Scheduler has been shut down
2021-12-02 14:34:45,368 - WARNING - Exiting immediately!
